Traceback (most recent call last):
  File "C:\ProgramData\miniconda3\Lib\site-packages\jupyter_cache\executors\utils.py", line 58, in single_nb_execution
    executenb(
  File "C:\ProgramData\miniconda3\Lib\site-packages\nbclient\client.py", line 1204, in execute
    return NotebookClient(nb=nb, resources=resources, km=km, **kwargs).execute()
           ^^^^^^^^^^^^^^^^^^^^^^^^^^^^^^^^^^^^^^^^^^^^^^^^^^^^^^^^^^^^^^^^^^^^^
  File "C:\ProgramData\miniconda3\Lib\site-packages\nbclient\util.py", line 84, in wrapped
    return just_run(coro(*args, **kwargs))
           ^^^^^^^^^^^^^^^^^^^^^^^^^^^^^^^
  File "C:\ProgramData\miniconda3\Lib\site-packages\nbclient\util.py", line 62, in just_run
    return loop.run_until_complete(coro)
           ^^^^^^^^^^^^^^^^^^^^^^^^^^^^^
  File "C:\ProgramData\miniconda3\Lib\asyncio\base_events.py", line 653, in run_until_complete
    return future.result()
           ^^^^^^^^^^^^^^^
  File "C:\ProgramData\miniconda3\Lib\site-packages\nbclient\client.py", line 663, in async_execute
    await self.async_execute_cell(
  File "C:\ProgramData\miniconda3\Lib\site-packages\nbclient\client.py", line 965, in async_execute_cell
    await self._check_raise_for_error(cell, cell_index, exec_reply)
  File "C:\ProgramData\miniconda3\Lib\site-packages\nbclient\client.py", line 862, in _check_raise_for_error
    raise CellExecutionError.from_cell_and_msg(cell, exec_reply_content)
nbclient.exceptions.CellExecutionError: An error occurred while executing the following cell:
------------------
import ipystata
------------------

[1;31m---------------------------------------------------------------------------[0m
[1;31mModuleNotFoundError[0m                       Traceback (most recent call last)
Cell [1;32mIn[1], line 1[0m
[1;32m----> 1[0m [38;5;28;01mimport[39;00m [38;5;21;01mipystata[39;00m

File [1;32mC:\ProgramData\miniconda3\Lib\site-packages\ipystata\__init__.py:8[0m
[0;32m      5[0m os_windows [38;5;241m=[39m platform[38;5;241m.[39msystem() [38;5;241m==[39m [38;5;124m'[39m[38;5;124mWindows[39m[38;5;124m'[39m
[0;32m      7[0m [38;5;28;01mif[39;00m os_windows [38;5;129;01mand[39;00m [38;5;129;01mnot[39;00m config[38;5;241m.[39mbatch_mode:
[1;32m----> 8[0m     [38;5;28;01mfrom[39;00m [38;5;21;01m.[39;00m [38;5;28;01mimport[39;00m ipystata_magic
[0;32m      9[0m [38;5;28;01melse[39;00m:
[0;32m     10[0m     [38;5;28;01mfrom[39;00m [38;5;21;01m.[39;00m [38;5;28;01mimport[39;00m ipystata_magic_batch

File [1;32mC:\ProgramData\miniconda3\Lib\site-packages\ipystata\ipystata_magic.py:21[0m
[0;32m     18[0m     [38;5;28;01mfrom[39;00m [38;5;21;01mIPython[39;00m[38;5;21;01m.[39;00m[38;5;21;01mpaths[39;00m [38;5;28;01mimport[39;00m get_ipython_cache_dir
[0;32m     20[0m [38;5;28;01mimport[39;00m [38;5;21;01mtime[39;00m
[1;32m---> 21[0m [38;5;28;01mimport[39;00m [38;5;21;01mpandas[39;00m [38;5;28;01mas[39;00m [38;5;21;01mpd[39;00m
[0;32m     22[0m [38;5;28;01mimport[39;00m [38;5;21;01msys[39;00m
[0;32m     23[0m [38;5;28;01mimport[39;00m [38;5;21;01msubprocess[39;00m

[1;31mModuleNotFoundError[0m: No module named 'pandas'
ModuleNotFoundError: No module named 'pandas'

